Workbook

Sheet DASHBOARD THỐNG KÊ
A1: BẢNG ĐIỀU KHIỂN (DASHBOARD) - TỔNG HỢP & PHÂN TÍCH LỖI KIỂM TRA PHÒNG CHỨC NĂNG (ĐOÀN 2)
A3: Chọn Phòng kiểm tra: | B3: Phản hồi - Phòng Điều dưỡng | C3: 👉 NÚT CẬP NHẬT: | D3: FALSE | E3: Tích chọn để tự động đồng bộ kết quả mới nhất
A5: TỔNG ĐIỂM CHUNG CỦA PHÒNG CHỨC NĂNG (TẤT CẢ THÀNH VIÊN ĐÃ CHẤM): | B5: 0 ĐIỂM
A7: 1. TỔNG SỐ ĐIỂM ĐẠT THEO TỪNG THÀNH VIÊN ĐÃ CHẤM
A8: Tên Thành Viên Đoàn Kiểm Tra (Đoàn 2) | B8: Tổng Điểm Đạt
A9: Phòng này chưa có dữ liệu nộp phiếu chấm đợt này.
A12: 2. CHI TIẾT NỘI DUNG KHÔNG ĐẠT ĐIỂM TỐI ĐA (PHÁT HIỆN LỖI)
A13: Nội dung tiêu chí kiểm tra | B13: Điểm chấm / Tối đa | C13: Thành viên chấm nội dung
A14: 🎉 Tuyệt vời! Phòng đạt điểm tối đa ở tất cả các tiêu chí đã chấm.
A17: 3. CHI TIẾT CÁC PHÁT HIỆN / GHI CHÚ / YÊU CẦU KHẮC PHỤC BẮT BUỘC
A18: Nội dung phát hiện thực tế & Yêu cầu cải tiến chất lượng | C18: Thành viên ghi nhận lỗi
A19: Không có ghi chú hoặc lỗi phát hiện đặc biệt nào được nhập.

Sheet Danh Sách Link Form ĐOÀN 2
A1: STT | B1: TÊN PHÒNG KIỂM TRA | C1: LINK GỬI CHO THÀNH VIÊN ĐOÀN 2
A2: 1 | B2: Phòng Công tác xã hội | C2: https://docs.google.com/forms/d/e/1FAIpQLScQynTKiUrR6Ps5BIwuk2MlrusqVGwi3lK9D2PTjUyWaqrzIw/viewform
A3: 2 | B3: Phòng Hành chánh quản trị | C3: https://docs.google.com/forms/d/e/1FAIpQLSfbJz8Qr2_xQq5yueZVmWTGYINpAajZn1zBQ79cu4_Zf1XptA/viewform
A4: 3 | B4: Phòng Kế hoạch tổng hợp | C4: https://docs.google.com/forms/d/e/1FAIpQLScqf_JtC5MEZ1sHNJZr3MCZnzSabbPor5GXh4a7mOKX73i6hg/viewform
A5: 4 | B5: Phòng Quản lý chất lượng | C5: https://docs.google.com/forms/d/e/1FAIpQLScgTWmNIPf4ro8I3iDEGfKiIXCKFv2iWgBedSP4aI_qzvZxaw/viewform
A6: 5 | B6: Phòng Tài chánh kế toán | C6: https://docs.google.com/forms/d/e/1FAIpQLSeZRcUIISro7qJAaYP2J7SooI7ZVjXTfmAGdMTcclyf6RTmHw/viewform
A7: 6 | B7: Phòng Tổ chức cán bộ | C7: https://docs.google.com/forms/d/e/1FAIpQLScrk8I0DGDZfnHuxXKvw-4sHTD4GNd-GBOTp3x-kWgzFNr87A/viewform
A8: 7 | B8: Phòng Vật tư thiết bị y tế | C8: https://docs.google.com/forms/d/e/1FAIpQLSc1u6-ptFoeBlT4n8GG8-9eyyQ43LP2uk4ikfMSFf-YlfGixw/viewform
A9: 8 | B9: Phòng Điều dưỡng | C9: https://docs.google.com/forms/d/e/1FAIpQLSeubWgiuqrYbtr9CtugInXhXYvP4t8mY0wIxsvTluKVL5Ac-w/viewform

Sheet Phản hồi - Phòng Điều dưỡng
A1: Dấu thời gian | B1: XÁC NHẬN THÀNH VIÊN ĐOÀN 02 THỰC HIỆN CHẤM ĐIỂM | C1: Tiêu chí 4: Nhân viên có mặt đúng giờ, đúng vị trí; trang phục, bảng tên, giao tiếp, tác phong hành chính đúng quy định. - Minh chứng: Bảng chấm công, lịch trực/làm việc, quan sát trực tiếp | D1: Tiêu chí 5: Không sử dụng thời gian làm việc cho việc cá nhân không phù hợp nhiệm vụ; không để tồn đọng công việc do lỗi chủ quan. - Minh chứng: Quan sát, phản ánh, hồ sơ công việc tồn đọng, biên bản nhắc nhở | E1: Ghi chú / Phát hiện / Yêu cầu khắc phục của Bà Phan Hồng Trên | F1: Tiêu chí 2: Thực hiện báo cáo định kỳ/đột xuất đúng thời hạn, đúng biểu mẫu, số liệu thống nhất với hồ sơ gốc. - Minh chứng: Báo cáo tháng/quý, sổ giao nhận, email/văn bản gửi, file dữ liệu | G1: Tiêu chí 3: Lưu trữ văn bản, hồ sơ, sổ sách của phòng đầy đủ, dễ tra cứu, có phân loại và kiểm soát phiên bản. - Minh chứng: Hồ sơ lưu, danh mục hồ sơ, bìa hồ sơ, file điện tử | H1: Ghi chú / Phát hiện / Yêu cầu khắc phục của Bà Trần Kim Diệu | I1: Tiêu chí 1: Có kế hoạch công tác tháng/tuần, phân công nhiệm vụ cụ thể, cập nhật tiến độ thực hiện và có bằng chứng điều hành. - Minh chứng: Kế hoạch công tác, lịch phân công, biên bản giao ban, bảng theo dõi tiến độ | J1: Ghi chú / Phát hiện / Yêu cầu khắc phục của Bà Trần Thiên Lý | K1: Tiêu chí 10: Quản lý, sử dụng tài sản công, trang thiết bị, vật tư văn phòng tiết kiệm; có sổ theo dõi và bàn giao khi thay đổi người sử dụng. - Minh chứng: Sổ tài sản, biên bản bàn giao, phiếu cấp phát, kiểm kê | L1: Tiêu chí 11: Thực hiện tiết kiệm điện, nước, văn phòng phẩm; khu vực làm việc gọn gàng, xanh - sạch - đẹp, không nguy cơ cháy nổ. - Minh chứng: Quan sát thực tế, bảng nhắc tiết kiệm, tình trạng ổ điện, vật dụng | M1: Tiêu chí 12: Chấp hành quy định an toàn, trật tự, kiểm soát ra vào; phối hợp ngăn ngừa buôn bán, quảng cáo hàng rong, taxi/xe dịch vụ chèo kéo trong phạm vi quản lý. - Minh chứng: Quan sát, phản ánh, biên bản xử lý, phối hợp bảo vệ | N1: Ghi chú / Phát hiện / Yêu cầu khắc phục của Ông Dương Quốc Huy | O1: Tiêu chí 13: Khu vực làm việc, kho hồ sơ, nơi tiếp nhận người bệnh/người nhà nếu có bảo đảm vệ sinh, phân loại rác, phòng chống lây nhiễm phù hợp. - Minh chứng: Quan sát, thùng rác, vệ sinh bề mặt, hướng dẫn vệ sinh tay | P1: Tiêu chí 14: Khi tiếp xúc người bệnh/người nhà/nhân viên, thực hiện giao tiếp ứng xử đúng quy định, hướng dẫn rõ ràng, tôn trọng và bảo mật thông tin. - Minh chứng: Quan sát, phản ánh, phiếu khảo sát, hồ sơ tiếp nhận xử lý | Q1: Tiêu chí 16: Tham mưu quản lý công tác điều dưỡng, hộ sinh, kỹ thuật viên; kiểm tra thực hiện quy trình chăm sóc tại khoa lâm sàng/cận lâm sàng. - Minh chứng: Kế hoạch điều dưỡng, biên bản giám sát, bảng kiểm chăm sóc | R1: Tiêu chí 17: Theo dõi tuân thủ 5 đúng, 3 kiểm tra, 5 đối chiếu, nhận diện người bệnh, phòng ngừa té ngã và bàn giao người bệnh. - Minh chứng: Bảng kiểm điều dưỡng, hồ sơ chăm sóc, phiếu nguy cơ té ngã | S1: Tiêu chí 18: Tổ chức đào tạo, kiểm tra tay nghề, giao tiếp ứng xử và giáo dục sức khỏe cho người bệnh/người nhà. - Minh chứng: Kế hoạch đào tạo, danh sách tham dự, tài liệu giáo dục sức khỏe | T1: Tiêu chí 20: Giám sát vệ sinh tay, phương tiện phòng hộ, xử lý dụng cụ và phối hợp KSNK trong toàn viện. - Minh chứng: Bảng kiểm vệ sinh tay, PPE, biên bản phối hợp KSNK | U1: Ghi chú / Phát hiện / Yêu cầu khắc phục của Ông Trương Văn Khanh | V1: Tiêu chí 6: Có theo dõi chỉ tiêu/KPI/BI được giao; phát hiện vấn đề và đề xuất cải tiến trong phạm vi chức năng. - Minh chứng: Bảng theo dõi KPI/BI, báo cáo phân tích, kế hoạch cải tiến | W1: Tiêu chí 7: Thực hiện khắc phục sau kiểm tra/giám sát đúng thời hạn; có bằng chứng CAPA và đánh giá hiệu lực. - Minh chứng: Biên bản kiểm tra, kế hoạch CAPA, minh chứng hoàn thành | X1: Tiêu chí 8: Tuân thủ bảo mật thông tin, không chia sẻ tài khoản/mật khẩu; dữ liệu, văn bản điện tử được phân quyền và sao lưu phù hợp. - Minh chứng: Tài khoản phần mềm, phân quyền, nhật ký truy cập, hồ sơ sao lưu | Y1: Tiêu chí 9: Máy tính, phần mềm, email công vụ và thiết bị lưu trữ được sử dụng đúng mục đích; không cài đặt phần mềm không rõ nguồn gốc. - Minh chứng: Kiểm tra máy trạm, phần mềm, email, USB/ổ cứng nếu có | Z1: Tiêu chí 15: Có ghi nhận, xử lý phản ánh, kiến nghị, khảo sát sự hài lòng liên quan đến phạm vi phòng; chuyển đúng đầu mối khi vượt thẩm quyền. - Minh chứng: Sổ/phần mềm phản ánh, phiếu khảo sát, biên bản xử lý | AA1: Tiêu chí 19: Theo dõi chỉ số điều dưỡng, sự cố liên quan chăm sóc, phản ánh người bệnh và đề xuất cải tiến. - Minh chứng: Báo cáo chỉ số điều dưỡng, sự cố, phản ánh, CAPA | AB1: Ghi chú / Phát hiện / Yêu cầu khắc phục của Ông Trần Việt Hùng | AC1: TỔNG ĐIỂM PHÒNG | AD1: TỔNG HỢP NHẬN XÉT

Sheet Phản hồi - Phòng Tổ chức cán bộ
A1: Dấu thời gian | B1: XÁC NHẬN THÀNH VIÊN ĐOÀN 02 THỰC HIỆN CHẤM ĐIỂM | C1: Tiêu chí 4: Nhân viên có mặt đúng giờ, đúng vị trí; trang phục, bảng tên, giao tiếp, tác phong hành chính đúng quy định. - Minh chứng: Bảng chấm công, lịch trực/làm việc, quan sát trực tiếp | D1: Tiêu chí 5: Không sử dụng thời gian làm việc cho việc cá nhân không phù hợp nhiệm vụ; không để tồn đọng công việc do lỗi chủ quan. - Minh chứng: Quan sát, phản ánh, hồ sơ công việc tồn đọng, biên bản nhắc nhở | E1: Tiêu chí 16: Quản lý hồ sơ viên chức/người lao động đầy đủ, cập nhật, bảo mật và dễ truy xuất khi cần. - Minh chứng: Hồ sơ nhân sự, danh mục hồ sơ, phân quyền lưu trữ | F1: Tiêu chí 17: Theo dõi chấm công, nghỉ phép, trực, ra trực, kỷ luật lao động và tham mưu xử lý đúng quy định. - Minh chứng: Bảng chấm công, đơn phép, lịch trực, biên bản xử lý | G1: Tiêu chí 18: Tham mưu tuyển dụng, bổ nhiệm, điều động, đánh giá, đào tạo theo vị trí việc làm và nhu cầu bệnh viện. - Minh chứng: Kế hoạch nhân sự, hồ sơ tuyển dụng/bổ nhiệm/đào tạo | H1: Ghi chú / Phát hiện / Yêu cầu khắc phục của Bà Phan Hồng Trên | I1: Tiêu chí 2: Thực hiện báo cáo định kỳ/đột xuất đúng thời hạn, đúng biểu mẫu, số liệu thống nhất với hồ sơ gốc. - Minh chứng: Báo cáo tháng/quý, sổ giao nhận, email/văn bản gửi, file dữ liệu | J1: Tiêu chí 3: Lưu trữ văn bản, hồ sơ, sổ sách của phòng đầy đủ, dễ tra cứu, có phân loại và kiểm soát phiên bản. - Minh chứng: Hồ sơ lưu, danh mục hồ sơ, bìa hồ sơ, file điện tử | K1: Tiêu chí 19: Báo cáo nhân lực, cơ cấu chuyên môn, chứng chỉ hành nghề, đào tạo liên tục chính xác và đúng hạn. - Minh chứng: Báo cáo nhân sự, danh sách chứng chỉ, CME, văn bản gửi cấp trên | L1: Ghi chú / Phát hiện / Yêu cầu khắc phục của Bà Trần Kim Diệu | M1: Tiêu chí 1: Có kế hoạch công tác tháng/tuần, phân công nhiệm vụ cụ thể, cập nhật tiến độ thực hiện và có bằng chứng điều hành. - Minh chứng: Kế hoạch công tác, lịch phân công, biên bản giao ban, bảng theo dõi tiến độ | N1: Ghi chú / Phát hiện / Yêu cầu khắc phục của Bà Trần Thiên Lý | O1: Tiêu chí 10: Quản lý, sử dụng tài sản công, trang thiết bị, vật tư văn phòng tiết kiệm; có sổ theo dõi và bàn giao khi thay đổi người sử dụng. - Minh chứng: Sổ tài sản, biên bản bàn giao, phiếu cấp phát, kiểm kê | P1: Tiêu chí 11: Thực hiện tiết kiệm điện, nước, văn phòng phẩm; khu vực làm việc gọn gàng, xanh - sạch - đẹp, không nguy cơ cháy nổ. - Minh chứng: Quan sát thực tế, bảng nhắc tiết kiệm, tình trạng ổ điện, vật dụng | Q1: Tiêu chí 12: Chấp hành quy định an toàn, trật tự, kiểm soát ra vào; phối hợp ngăn ngừa buôn bán, quảng cáo hàng rong, taxi/xe dịch vụ chèo kéo trong phạm vi quản lý. - Minh chứng: Quan sát, phản ánh, biên bản xử lý, phối hợp bảo vệ | R1: Ghi chú / Phát hiện / Yêu cầu khắc phục của Ông Dương Quốc Huy | S1: Tiêu chí 13: Khu vực làm việc, kho hồ sơ, nơi tiếp nhận người bệnh/người nhà nếu có bảo đảm vệ sinh, phân loại rác, phòng chống lây nhiễm phù hợp. - Minh chứng: Quan sát, thùng rác, vệ sinh bề mặt, hướng dẫn vệ sinh tay | T1: Tiêu chí 14: Khi tiếp xúc người bệnh/người nhà/nhân viên, thực hiện giao tiếp ứng xử đúng quy định, hướng dẫn rõ ràng, tôn trọng và bảo mật thông tin. - Minh chứng: Quan sát, phản ánh, phiếu khảo sát, hồ sơ tiếp nhận xử lý | U1: Ghi chú / Phát hiện / Yêu cầu khắc phục của Ông Trương Văn Khanh | V1: Tiêu chí 6: Có theo dõi chỉ tiêu/KPI/BI được giao; phát hiện vấn đề và đề xuất cải tiến trong phạm vi chức năng. - Minh chứng: Bảng theo dõi KPI/BI, báo cáo phân tích, kế hoạch cải tiến | W1: Tiêu chí 7: Thực hiện khắc phục sau kiểm tra/giám sát đúng thời hạn; có bằng chứng CAPA và đánh giá hiệu lực. - Minh chứng: Biên bản kiểm tra, kế hoạch CAPA, minh chứng hoàn thành | X1: Tiêu chí 8: Tuân thủ bảo mật thông tin, không chia sẻ tài khoản/mật khẩu; dữ liệu, văn bản điện tử được phân quyền và sao lưu phù hợp. - Minh chứng: Tài khoản phần mềm, phân quyền, nhật ký truy cập, hồ sơ sao lưu | Y1: Tiêu chí 9: Máy tính, phần mềm, email công vụ và thiết bị lưu trữ được sử dụng đúng mục đích; không cài đặt phần mềm không rõ nguồn gốc. - Minh chứng: Kiểm tra máy trạm, phần mềm, email, USB/ổ cứng nếu có | Z1: Tiêu chí 15: Có ghi nhận, xử lý phản ánh, kiến nghị, khảo sát sự hài lòng liên quan đến phạm vi phòng; chuyển đúng đầu mối khi vượt thẩm quyền. - Minh chứng: Sổ/phần mềm phản ánh, phiếu khảo sát, biên bản xử lý | AA1: Tiêu chí 20: Bảo mật dữ liệu nhân sự, tiền lương, đánh giá, kỷ luật; không cung cấp thông tin khi chưa đúng thẩm quyền. - Minh chứng: Hồ sơ phân quyền, nhật ký cung cấp thông tin, quy trình bảo mật | AB1: Ghi chú / Phát hiện / Yêu cầu khắc phục của Ông Trần Việt Hùng | AC1: TỔNG ĐIỂM PHÒNG | AD1: TỔNG HỢP NHẬN XÉT

Sheet Phản hồi - Phòng Vật tư thiết b
A1: Dấu thời gian | B1: XÁC NHẬN THÀNH VIÊN ĐOÀN 02 THỰC HIỆN CHẤM ĐIỂM | C1: Tiêu chí 16: Lập kế hoạch, theo dõi cung ứng vật tư, hóa chất, trang thiết bị y tế phù hợp nhu cầu chuyên môn và dự trù được duyệt. - Minh chứng: Kế hoạch mua sắm, dự trù, phiếu cấp phát, báo cáo tồn kho | D1: Tiêu chí 17: Quản lý hồ sơ thiết bị y tế: lý lịch máy, bảo trì, bảo dưỡng, hiệu chuẩn/kiểm định và tình trạng sử dụng. - Minh chứng: Lý lịch máy, hợp đồng bảo trì, tem kiểm định, biên bản sửa chữa | E1: Tiêu chí 18: Kiểm soát nhập - xuất - tồn vật tư, hóa chất, hạn dùng, điều kiện bảo quản và cảnh báo thiếu/hết hàng. - Minh chứng: Sổ kho, phần mềm, thẻ kho, biên bản kiểm kê, cảnh báo tồn | F1: Ghi chú / Phát hiện / Yêu cầu khắc phục của Bà Lưu Thị Thu Cầm | G1: Tiêu chí 4: Nhân viên có mặt đúng giờ, đúng vị trí; trang phục, bảng tên, giao tiếp, tác phong hành chính đúng quy định. - Minh chứng: Bảng chấm công, lịch trực/làm việc, quan sát trực tiếp | H1: Tiêu chí 5: Không sử dụng thời gian làm việc cho việc cá nhân không phù hợp nhiệm vụ; không để tồn đọng công việc do lỗi chủ quan. - Minh chứng: Quan sát, phản ánh, hồ sơ công việc tồn đọng, biên bản nhắc nhở | I1: Ghi chú / Phát hiện / Yêu cầu khắc phục của Bà Phan Hồng Trên | J1: Tiêu chí 2: Thực hiện báo cáo định kỳ/đột xuất đúng thời hạn, đúng biểu mẫu, số liệu thống nhất với hồ sơ gốc. - Minh chứng: Báo cáo tháng/quý, sổ giao nhận, email/văn bản gửi, file dữ liệu | K1: Tiêu chí 3: Lưu trữ văn bản, hồ sơ, sổ sách của phòng đầy đủ, dễ tra cứu, có phân loại và kiểm soát phiên bản. - Minh chứng: Hồ sơ lưu, danh mục hồ sơ, bìa hồ sơ, file điện tử | L1: Ghi chú / Phát hiện / Yêu cầu khắc phục của Bà Trần Kim Diệu | M1: Tiêu chí 1: Có kế hoạch công tác tháng/tuần, phân công nhiệm vụ cụ thể, cập nhật tiến độ thực hiện và có bằng chứng điều hành. - Minh chứng: Kế hoạch công tác, lịch phân công, biên bản giao ban, bảng theo dõi tiến độ | N1: Ghi chú / Phát hiện / Yêu cầu khắc phục của Bà Trần Thiên Lý | O1: Tiêu chí 10: Quản lý, sử dụng tài sản công, trang thiết bị, vật tư văn phòng tiết kiệm; có sổ theo dõi và bàn giao khi thay đổi người sử dụng. - Minh chứng: Sổ tài sản, biên bản bàn giao, phiếu cấp phát, kiểm kê | P1: Tiêu chí 11: Thực hiện tiết kiệm điện, nước, văn phòng phẩm; khu vực làm việc gọn gàng, xanh - sạch - đẹp, không nguy cơ cháy nổ. - Minh chứng: Quan sát thực tế, bảng nhắc tiết kiệm, tình trạng ổ điện, vật dụng | Q1: Tiêu chí 12: Chấp hành quy định an toàn, trật tự, kiểm soát ra vào; phối hợp ngăn ngừa buôn bán, quảng cáo hàng rong, taxi/xe dịch vụ chèo kéo trong phạm vi quản lý. - Minh chứng: Quan sát, phản ánh, biên bản xử lý, phối hợp bảo vệ | R1: Tiêu chí 19: Phối hợp khoa/phòng xử lý hỏng hóc trang thiết bị, vật tư không phù hợp và đề xuất thay thế/sửa chữa kịp thời. - Minh chứng: Phiếu báo hỏng, biên bản đánh giá, đề xuất sửa chữa/thay thế | S1: Ghi chú / Phát hiện / Yêu cầu khắc phục của Ông Dương Quốc Huy | T1: Tiêu chí 13: Khu vực làm việc, kho hồ sơ, nơi tiếp nhận người bệnh/người nhà nếu có bảo đảm vệ sinh, phân loại rác, phòng chống lây nhiễm phù hợp. - Minh chứng: Quan sát, thùng rác, vệ sinh bề mặt, hướng dẫn vệ sinh tay | U1: Tiêu chí 14: Khi tiếp xúc người bệnh/người nhà/nhân viên, thực hiện giao tiếp ứng xử đúng quy định, hướng dẫn rõ ràng, tôn trọng và bảo mật thông tin. - Minh chứng: Quan sát, phản ánh, phiếu khảo sát, hồ sơ tiếp nhận xử lý | V1: Ghi chú / Phát hiện / Yêu cầu khắc phục của Ông Trương Văn Khanh | W1: Tiêu chí 6: Có theo dõi chỉ tiêu/KPI/BI được giao; phát hiện vấn đề và đề xuất cải tiến trong phạm vi chức năng. - Minh chứng: Bảng theo dõi KPI/BI, báo cáo phân tích, kế hoạch cải tiến | X1: Tiêu chí 7: Thực hiện khắc phục sau kiểm tra/giám sát đúng thời hạn; có bằng chứng CAPA và đánh giá hiệu lực. - Minh chứng: Biên bản kiểm tra, kế hoạch CAPA, minh chứng hoàn thành | Y1: Tiêu chí 8: Tuân thủ bảo mật thông tin, không chia sẻ tài khoản/mật khẩu; dữ liệu, văn bản điện tử được phân quyền và sao lưu phù hợp. - Minh chứng: Tài khoản phần mềm, phân quyền, nhật ký truy cập, hồ sơ sao lưu | Z1: Tiêu chí 9: Máy tính, phần mềm, email công vụ và thiết bị lưu trữ được sử dụng đúng mục đích; không cài đặt phần mềm không rõ nguồn gốc. - Minh chứng: Kiểm tra máy trạm, phần mềm, email, USB/ổ cứng nếu có | AA1: Tiêu chí 15: Có ghi nhận, xử lý phản ánh, kiến nghị, khảo sát sự hài lòng liên quan đến phạm vi phòng; chuyển đúng đầu mối khi vượt thẩm quyền. - Minh chứng: Sổ/phần mềm phản ánh, phiếu khảo sát, biên bản xử lý | AB1: Tiêu chí 20: Bảo mật hồ sơ đấu thầu, mua sắm, báo giá, hợp đồng và dữ liệu tồn kho theo phân quyền. - Minh chứng: Hồ sơ mua sắm, phân quyền thư mục/phần mềm, nhật ký truy cập | AC1: Ghi chú / Phát hiện / Yêu cầu khắc phục của Ông Trần Việt Hùng | AD1: TỔNG ĐIỂM PHÒNG | AE1: TỔNG HỢP NHẬN XÉT

Sheet Phản hồi - Phòng Tài chánh kế t
A1: Dấu thời gian | B1: XÁC NHẬN THÀNH VIÊN ĐOÀN 02 THỰC HIỆN CHẤM ĐIỂM | C1: Tiêu chí 4: Nhân viên có mặt đúng giờ, đúng vị trí; trang phục, bảng tên, giao tiếp, tác phong hành chính đúng quy định. - Minh chứng: Bảng chấm công, lịch trực/làm việc, quan sát trực tiếp | D1: Tiêu chí 5: Không sử dụng thời gian làm việc cho việc cá nhân không phù hợp nhiệm vụ; không để tồn đọng công việc do lỗi chủ quan. - Minh chứng: Quan sát, phản ánh, hồ sơ công việc tồn đọng, biên bản nhắc nhở | E1: Ghi chú / Phát hiện / Yêu cầu khắc phục của Bà Phan Hồng Trên | F1: Tiêu chí 2: Thực hiện báo cáo định kỳ/đột xuất đúng thời hạn, đúng biểu mẫu, số liệu thống nhất với hồ sơ gốc. - Minh chứng: Báo cáo tháng/quý, sổ giao nhận, email/văn bản gửi, file dữ liệu | G1: Tiêu chí 3: Lưu trữ văn bản, hồ sơ, sổ sách của phòng đầy đủ, dễ tra cứu, có phân loại và kiểm soát phiên bản. - Minh chứng: Hồ sơ lưu, danh mục hồ sơ, bìa hồ sơ, file điện tử | H1: Tiêu chí 16: Thực hiện thu, chi, hạch toán, quyết toán, báo cáo tài chính, báo cáo bảo hiểm đúng quy định và đúng thời hạn. - Minh chứng: Báo cáo tài chính, chứng từ, sổ kế toán, báo cáo BHYT | I1: Ghi chú / Phát hiện / Yêu cầu khắc phục của Bà Trần Kim Diệu | J1: Tiêu chí 1: Có kế hoạch công tác tháng/tuần, phân công nhiệm vụ cụ thể, cập nhật tiến độ thực hiện và có bằng chứng điều hành. - Minh chứng: Kế hoạch công tác, lịch phân công, biên bản giao ban, bảng theo dõi tiến độ | K1: Ghi chú / Phát hiện / Yêu cầu khắc phục của Bà Trần Thiên Lý | L1: Tiêu chí 10: Quản lý, sử dụng tài sản công, trang thiết bị, vật tư văn phòng tiết kiệm; có sổ theo dõi và bàn giao khi thay đổi người sử dụng. - Minh chứng: Sổ tài sản, biên bản bàn giao, phiếu cấp phát, kiểm kê | M1: Tiêu chí 11: Thực hiện tiết kiệm điện, nước, văn phòng phẩm; khu vực làm việc gọn gàng, xanh - sạch - đẹp, không nguy cơ cháy nổ. - Minh chứng: Quan sát thực tế, bảng nhắc tiết kiệm, tình trạng ổ điện, vật dụng | N1: Tiêu chí 12: Chấp hành quy định an toàn, trật tự, kiểm soát ra vào; phối hợp ngăn ngừa buôn bán, quảng cáo hàng rong, taxi/xe dịch vụ chèo kéo trong phạm vi quản lý. - Minh chứng: Quan sát, phản ánh, biên bản xử lý, phối hợp bảo vệ | O1: Tiêu chí 17: Kiểm soát viện phí, tạm ứng, hoàn ứng, miễn giảm và công khai tài chính theo quy định. - Minh chứng: Biên lai, bảng kê, hồ sơ miễn giảm, công khai tài chính | P1: Tiêu chí 18: Quản lý tài sản, công cụ dụng cụ về mặt giá trị, kiểm kê, thanh lý, mua sắm phối hợp đúng quy trình. - Minh chứng: Biên bản kiểm kê, hồ sơ thanh lý, phiếu nhập xuất, phối hợp VT-HCQT | Q1: Ghi chú / Phát hiện / Yêu cầu khắc phục của Ông Dương Quốc Huy | R1: Tiêu chí 13: Khu vực làm việc, kho hồ sơ, nơi tiếp nhận người bệnh/người nhà nếu có bảo đảm vệ sinh, phân loại rác, phòng chống lây nhiễm phù hợp. - Minh chứng: Quan sát, thùng rác, vệ sinh bề mặt, hướng dẫn vệ sinh tay | S1: Tiêu chí 14: Khi tiếp xúc người bệnh/người nhà/nhân viên, thực hiện giao tiếp ứng xử đúng quy định, hướng dẫn rõ ràng, tôn trọng và bảo mật thông tin. - Minh chứng: Quan sát, phản ánh, phiếu khảo sát, hồ sơ tiếp nhận xử lý | T1: Ghi chú / Phát hiện / Yêu cầu khắc phục của Ông Trương Văn Khanh | U1: Tiêu chí 6: Có theo dõi chỉ tiêu/KPI/BI được giao; phát hiện vấn đề và đề xuất cải tiến trong phạm vi chức năng. - Minh chứng: Bảng theo dõi KPI/BI, báo cáo phân tích, kế hoạch cải tiến | V1: Tiêu chí 7: Thực hiện khắc phục sau kiểm tra/giám sát đúng thời hạn; có bằng chứng CAPA và đánh giá hiệu lực. - Minh chứng: Biên bản kiểm tra, kế hoạch CAPA, minh chứng hoàn thành | W1: Tiêu chí 8: Tuân thủ bảo mật thông tin, không chia sẻ tài khoản/mật khẩu; dữ liệu, văn bản điện tử được phân quyền và sao lưu phù hợp. - Minh chứng: Tài khoản phần mềm, phân quyền, nhật ký truy cập, hồ sơ sao lưu | X1: Tiêu chí 9: Máy tính, phần mềm, email công vụ và thiết bị lưu trữ được sử dụng đúng mục đích; không cài đặt phần mềm không rõ nguồn gốc. - Minh chứng: Kiểm tra máy trạm, phần mềm, email, USB/ổ cứng nếu có | Y1: Tiêu chí 15: Có ghi nhận, xử lý phản ánh, kiến nghị, khảo sát sự hài lòng liên quan đến phạm vi phòng; chuyển đúng đầu mối khi vượt thẩm quyền. - Minh chứng: Sổ/phần mềm phản ánh, phiếu khảo sát, biên bản xử lý | Z1: Tiêu chí 19: Bảo mật dữ liệu tài chính, viện phí, BHYT; phân quyền phần mềm và sao lưu dữ liệu kế toán. - Minh chứng: Phân quyền phần mềm, nhật ký truy cập, hồ sơ sao lưu | AA1: Tiêu chí 20: Theo dõi phản ánh liên quan thu viện phí, thanh toán, hướng dẫn người bệnh; xử lý sai sót kịp thời. - Minh chứng: Sổ phản ánh, biên bản xử lý, điều chỉnh hóa đơn/biên lai nếu có | AB1: Ghi chú / Phát hiện / Yêu cầu khắc phục của Ông Trần Việt Hùng | AC1: TỔNG ĐIỂM PHÒNG | AD1: TỔNG HỢP NHẬN XÉT

Sheet Phản hồi - Phòng Quản lý chất l
A1: Dấu thời gian | B1: XÁC NHẬN THÀNH VIÊN ĐOÀN 02 THỰC HIỆN CHẤM ĐIỂM | C1: Tiêu chí 4: Nhân viên có mặt đúng giờ, đúng vị trí; trang phục, bảng tên, giao tiếp, tác phong hành chính đúng quy định. - Minh chứng: Bảng chấm công, lịch trực/làm việc, quan sát trực tiếp | D1: Tiêu chí 5: Không sử dụng thời gian làm việc cho việc cá nhân không phù hợp nhiệm vụ; không để tồn đọng công việc do lỗi chủ quan. - Minh chứng: Quan sát, phản ánh, hồ sơ công việc tồn đọng, biên bản nhắc nhở | E1: Ghi chú / Phát hiện / Yêu cầu khắc phục của Bà Phan Hồng Trên | F1: Tiêu chí 2: Thực hiện báo cáo định kỳ/đột xuất đúng thời hạn, đúng biểu mẫu, số liệu thống nhất với hồ sơ gốc. - Minh chứng: Báo cáo tháng/quý, sổ giao nhận, email/văn bản gửi, file dữ liệu | G1: Tiêu chí 3: Lưu trữ văn bản, hồ sơ, sổ sách của phòng đầy đủ, dễ tra cứu, có phân loại và kiểm soát phiên bản. - Minh chứng: Hồ sơ lưu, danh mục hồ sơ, bìa hồ sơ, file điện tử | H1: Ghi chú / Phát hiện / Yêu cầu khắc phục của Bà Trần Kim Diệu | I1: Tiêu chí 1: Có kế hoạch công tác tháng/tuần, phân công nhiệm vụ cụ thể, cập nhật tiến độ thực hiện và có bằng chứng điều hành. - Minh chứng: Kế hoạch công tác, lịch phân công, biên bản giao ban, bảng theo dõi tiến độ | J1: Ghi chú / Phát hiện / Yêu cầu khắc phục của Bà Trần Thiên Lý | K1: Tiêu chí 10: Quản lý, sử dụng tài sản công, trang thiết bị, vật tư văn phòng tiết kiệm; có sổ theo dõi và bàn giao khi thay đổi người sử dụng. - Minh chứng: Sổ tài sản, biên bản bàn giao, phiếu cấp phát, kiểm kê | L1: Tiêu chí 11: Thực hiện tiết kiệm điện, nước, văn phòng phẩm; khu vực làm việc gọn gàng, xanh - sạch - đẹp, không nguy cơ cháy nổ. - Minh chứng: Quan sát thực tế, bảng nhắc tiết kiệm, tình trạng ổ điện, vật dụng | M1: Tiêu chí 12: Chấp hành quy định an toàn, trật tự, kiểm soát ra vào; phối hợp ngăn ngừa buôn bán, quảng cáo hàng rong, taxi/xe dịch vụ chèo kéo trong phạm vi quản lý. - Minh chứng: Quan sát, phản ánh, biên bản xử lý, phối hợp bảo vệ | N1: Ghi chú / Phát hiện / Yêu cầu khắc phục của Ông Dương Quốc Huy | O1: Tiêu chí 13: Khu vực làm việc, kho hồ sơ, nơi tiếp nhận người bệnh/người nhà nếu có bảo đảm vệ sinh, phân loại rác, phòng chống lây nhiễm phù hợp. - Minh chứng: Quan sát, thùng rác, vệ sinh bề mặt, hướng dẫn vệ sinh tay | P1: Tiêu chí 14: Khi tiếp xúc người bệnh/người nhà/nhân viên, thực hiện giao tiếp ứng xử đúng quy định, hướng dẫn rõ ràng, tôn trọng và bảo mật thông tin. - Minh chứng: Quan sát, phản ánh, phiếu khảo sát, hồ sơ tiếp nhận xử lý | Q1: Ghi chú / Phát hiện / Yêu cầu khắc phục của Ông Trương Văn Khanh | R1: Tiêu chí 6: Có theo dõi chỉ tiêu/KPI/BI được giao; phát hiện vấn đề và đề xuất cải tiến trong phạm vi chức năng. - Minh chứng: Bảng theo dõi KPI/BI, báo cáo phân tích, kế hoạch cải tiến | S1: Tiêu chí 7: Thực hiện khắc phục sau kiểm tra/giám sát đúng thời hạn; có bằng chứng CAPA và đánh giá hiệu lực. - Minh chứng: Biên bản kiểm tra, kế hoạch CAPA, minh chứng hoàn thành | T1: Tiêu chí 8: Tuân thủ bảo mật thông tin, không chia sẻ tài khoản/mật khẩu; dữ liệu, văn bản điện tử được phân quyền và sao lưu phù hợp. - Minh chứng: Tài khoản phần mềm, phân quyền, nhật ký truy cập, hồ sơ sao lưu | U1: Tiêu chí 9: Máy tính, phần mềm, email công vụ và thiết bị lưu trữ được sử dụng đúng mục đích; không cài đặt phần mềm không rõ nguồn gốc. - Minh chứng: Kiểm tra máy trạm, phần mềm, email, USB/ổ cứng nếu có | V1: Tiêu chí 15: Có ghi nhận, xử lý phản ánh, kiến nghị, khảo sát sự hài lòng liên quan đến phạm vi phòng; chuyển đúng đầu mối khi vượt thẩm quyền. - Minh chứng: Sổ/phần mềm phản ánh, phiếu khảo sát, biên bản xử lý | W1: Tiêu chí 16: Tham mưu và theo dõi kế hoạch cải tiến chất lượng bệnh viện; có chỉ số, mục tiêu, tiến độ và minh chứng kết quả. - Minh chứng: Kế hoạch QLCL, đề án cải tiến, bảng theo dõi chỉ số | X1: Tiêu chí 17: Quản lý sự cố y khoa, nguy cơ mất an toàn người bệnh, báo cáo và phân tích nguyên nhân gốc theo quy định. - Minh chứng: Sổ/phần mềm sự cố, báo cáo phân tích, biên bản họp | Y1: Tiêu chí 18: Tổ chức khảo sát hài lòng người bệnh, người nhà và nhân viên; phân tích, phản hồi, đề xuất cải tiến. - Minh chứng: Phiếu khảo sát, dữ liệu tổng hợp, báo cáo phân tích, kế hoạch cải tiến | Z1: Tiêu chí 19: Theo dõi Bộ tiêu chí chất lượng bệnh viện, chuẩn bị minh chứng và cảnh báo tiêu chí nguy cơ tụt mức. - Minh chứng: Bảng tự đánh giá tiêu chí, minh chứng, kế hoạch duy trì/cải tiến | AA1: Tiêu chí 20: Bảo mật dữ liệu khảo sát, sự cố và hồ sơ chất lượng; phân quyền, lưu trữ và công bố thông tin đúng quy định. - Minh chứng: Thư mục dữ liệu, phân quyền truy cập, hồ sơ công bố | AB1: Ghi chú / Phát hiện / Yêu cầu khắc phục của Ông Trần Việt Hùng | AC1: TỔNG ĐIỂM PHÒNG | AD1: TỔNG HỢP NHẬN XÉT

Sheet Phản hồi - Phòng Kế hoạch tổng 
A1: Dấu thời gian | B1: XÁC NHẬN THÀNH VIÊN ĐOÀN 02 THỰC HIỆN CHẤM ĐIỂM | C1: Tiêu chí 16: Tham mưu kế hoạch hoạt động bệnh viện, kế hoạch chuyên môn, giao ban, chỉ tiêu chuyên môn đúng tiến độ và phù hợp thực tế. - Minh chứng: Kế hoạch năm/quý/tháng, biên bản giao ban, chỉ tiêu chuyên môn | D1: Tiêu chí 18: Theo dõi hồ sơ bệnh án, mã hóa bệnh, ngày điều trị, chuyển tuyến, nhập/xuất viện và các chỉ số chuyên môn trọng yếu. - Minh chứng: Báo cáo HSBA, trích xuất HIS, danh sách kiểm tra | E1: Tiêu chí 20: Phối hợp chỉ đạo tuyến, đào tạo, hội chẩn/chuyển tuyến, phòng chống dịch và các nhiệm vụ chuyên môn liên khoa đúng phân công. - Minh chứng: Kế hoạch, báo cáo, biên bản phối hợp, hồ sơ chỉ đạo tuyến | F1: Ghi chú / Phát hiện / Yêu cầu khắc phục của Bà Huỳnh Thúy Hằng | G1: Tiêu chí 4: Nhân viên có mặt đúng giờ, đúng vị trí; trang phục, bảng tên, giao tiếp, tác phong hành chính đúng quy định. - Minh chứng: Bảng chấm công, lịch trực/làm việc, quan sát trực tiếp | H1: Tiêu chí 5: Không sử dụng thời gian làm việc cho việc cá nhân không phù hợp nhiệm vụ; không để tồn đọng công việc do lỗi chủ quan. - Minh chứng: Quan sát, phản ánh, hồ sơ công việc tồn đọng, biên bản nhắc nhở | I1: Ghi chú / Phát hiện / Yêu cầu khắc phục của Bà Phan Hồng Trên | J1: Tiêu chí 2: Thực hiện báo cáo định kỳ/đột xuất đúng thời hạn, đúng biểu mẫu, số liệu thống nhất với hồ sơ gốc. - Minh chứng: Báo cáo tháng/quý, sổ giao nhận, email/văn bản gửi, file dữ liệu | K1: Tiêu chí 3: Lưu trữ văn bản, hồ sơ, sổ sách của phòng đầy đủ, dễ tra cứu, có phân loại và kiểm soát phiên bản. - Minh chứng: Hồ sơ lưu, danh mục hồ sơ, bìa hồ sơ, file điện tử | L1: Tiêu chí 17: Tổng hợp số liệu hoạt động khám chữa bệnh, thống kê báo cáo cấp trên chính xác, thống nhất giữa HIS, khoa phòng và báo cáo gửi đi. - Minh chứng: Báo cáo KHTH, dữ liệu HIS, bảng đối chiếu, văn bản gửi SYT/BYT | M1: Ghi chú / Phát hiện / Yêu cầu khắc phục của Bà Trần Kim Diệu | N1: Tiêu chí 1: Có kế hoạch công tác tháng/tuần, phân công nhiệm vụ cụ thể, cập nhật tiến độ thực hiện và có bằng chứng điều hành. - Minh chứng: Kế hoạch công tác, lịch phân công, biên bản giao ban, bảng theo dõi tiến độ | O1: Tiêu chí 19: Điều phối công tác kiểm tra hoạt động bệnh viện; tổng hợp biên bản, kiến nghị và theo dõi khắc phục sau kiểm tra. - Minh chứng: Lịch kiểm tra, biên bản, bảng tổng hợp CAPA, báo cáo BGĐ | P1: Ghi chú / Phát hiện / Yêu cầu khắc phục của Bà Trần Thiên Lý | Q1: Tiêu chí 10: Quản lý, sử dụng tài sản công, trang thiết bị, vật tư văn phòng tiết kiệm; có sổ theo dõi và bàn giao khi thay đổi người sử dụng. - Minh chứng: Sổ tài sản, biên bản bàn giao, phiếu cấp phát, kiểm kê | R1: Tiêu chí 11: Thực hiện tiết kiệm điện, nước, văn phòng phẩm; khu vực làm việc gọn gàng, xanh - sạch - đẹp, không nguy cơ cháy nổ. - Minh chứng: Quan sát thực tế, bảng nhắc tiết kiệm, tình trạng ổ điện, vật dụng | S1: Tiêu chí 12: Chấp hành quy định an toàn, trật tự, kiểm soát ra vào; phối hợp ngăn ngừa buôn bán, quảng cáo hàng rong, taxi/xe dịch vụ chèo kéo trong phạm vi quản lý. - Minh chứng: Quan sát, phản ánh, biên bản xử lý, phối hợp bảo vệ | T1: Ghi chú / Phát hiện / Yêu cầu khắc phục của Ông Dương Quốc Huy | U1: Tiêu chí 13: Khu vực làm việc, kho hồ sơ, nơi tiếp nhận người bệnh/người nhà nếu có bảo đảm vệ sinh, phân loại rác, phòng chống lây nhiễm phù hợp. - Minh chứng: Quan sát, thùng rác, vệ sinh bề mặt, hướng dẫn vệ sinh tay | V1: Tiêu chí 14: Khi tiếp xúc người bệnh/người nhà/nhân viên, thực hiện giao tiếp ứng xử đúng quy định, hướng dẫn rõ ràng, tôn trọng và bảo mật thông tin. - Minh chứng: Quan sát, phản ánh, phiếu khảo sát, hồ sơ tiếp nhận xử lý | W1: Ghi chú / Phát hiện / Yêu cầu khắc phục của Ông Trương Văn Khanh | X1: Tiêu chí 6: Có theo dõi chỉ tiêu/KPI/BI được giao; phát hiện vấn đề và đề xuất cải tiến trong phạm vi chức năng. - Minh chứng: Bảng theo dõi KPI/BI, báo cáo phân tích, kế hoạch cải tiến | Y1: Tiêu chí 7: Thực hiện khắc phục sau kiểm tra/giám sát đúng thời hạn; có bằng chứng CAPA và đánh giá hiệu lực. - Minh chứng: Biên bản kiểm tra, kế hoạch CAPA, minh chứng hoàn thành | Z1: Tiêu chí 8: Tuân thủ bảo mật thông tin, không chia sẻ tài khoản/mật khẩu; dữ liệu, văn bản điện tử được phân quyền và sao lưu phù hợp. - Minh chứng: Tài khoản phần mềm, phân quyền, nhật ký truy cập, hồ sơ sao lưu | AA1: Tiêu chí 9: Máy tính, phần mềm, email công vụ và thiết bị lưu trữ được sử dụng đúng mục đích; không cài đặt phần mềm không rõ nguồn gốc. - Minh chứng: Kiểm tra máy trạm, phần mềm, email, USB/ổ cứng nếu có | AB1: Tiêu chí 15: Có ghi nhận, xử lý phản ánh, kiến nghị, khảo sát sự hài lòng liên quan đến phạm vi phòng; chuyển đúng đầu mối khi vượt thẩm quyền. - Minh chứng: Sổ/phần mềm phản ánh, phiếu khảo sát, biên bản xử lý | AC1: Ghi chú / Phát hiện / Yêu cầu khắc phục của Ông Trần Việt Hùng | AD1: TỔNG ĐIỂM PHÒNG | AE1: TỔNG HỢP NHẬN XÉT

Sheet Phản hồi - Phòng Hành chánh quả
A1: Dấu thời gian | B1: XÁC NHẬN THÀNH VIÊN ĐOÀN 02 THỰC HIỆN CHẤM ĐIỂM | C1: Tiêu chí 4: Nhân viên có mặt đúng giờ, đúng vị trí; trang phục, bảng tên, giao tiếp, tác phong hành chính đúng quy định. - Minh chứng: Bảng chấm công, lịch trực/làm việc, quan sát trực tiếp | D1: Tiêu chí 5: Không sử dụng thời gian làm việc cho việc cá nhân không phù hợp nhiệm vụ; không để tồn đọng công việc do lỗi chủ quan. - Minh chứng: Quan sát, phản ánh, hồ sơ công việc tồn đọng, biên bản nhắc nhở | E1: Ghi chú / Phát hiện / Yêu cầu khắc phục của Bà Phan Hồng Trên | F1: Tiêu chí 2: Thực hiện báo cáo định kỳ/đột xuất đúng thời hạn, đúng biểu mẫu, số liệu thống nhất với hồ sơ gốc. - Minh chứng: Báo cáo tháng/quý, sổ giao nhận, email/văn bản gửi, file dữ liệu | G1: Tiêu chí 3: Lưu trữ văn bản, hồ sơ, sổ sách của phòng đầy đủ, dễ tra cứu, có phân loại và kiểm soát phiên bản. - Minh chứng: Hồ sơ lưu, danh mục hồ sơ, bìa hồ sơ, file điện tử | H1: Ghi chú / Phát hiện / Yêu cầu khắc phục của Bà Trần Kim Diệu | I1: Tiêu chí 1: Có kế hoạch công tác tháng/tuần, phân công nhiệm vụ cụ thể, cập nhật tiến độ thực hiện và có bằng chứng điều hành. - Minh chứng: Kế hoạch công tác, lịch phân công, biên bản giao ban, bảng theo dõi tiến độ | J1: Ghi chú / Phát hiện / Yêu cầu khắc phục của Bà Trần Thiên Lý | K1: Tiêu chí 10: Quản lý, sử dụng tài sản công, trang thiết bị, vật tư văn phòng tiết kiệm; có sổ theo dõi và bàn giao khi thay đổi người sử dụng. - Minh chứng: Sổ tài sản, biên bản bàn giao, phiếu cấp phát, kiểm kê | L1: Tiêu chí 11: Thực hiện tiết kiệm điện, nước, văn phòng phẩm; khu vực làm việc gọn gàng, xanh - sạch - đẹp, không nguy cơ cháy nổ. - Minh chứng: Quan sát thực tế, bảng nhắc tiết kiệm, tình trạng ổ điện, vật dụng | M1: Tiêu chí 12: Chấp hành quy định an toàn, trật tự, kiểm soát ra vào; phối hợp ngăn ngừa buôn bán, quảng cáo hàng rong, taxi/xe dịch vụ chèo kéo trong phạm vi quản lý. - Minh chứng: Quan sát, phản ánh, biên bản xử lý, phối hợp bảo vệ | N1: Tiêu chí 16: Quản lý công văn, văn thư, lưu trữ, con dấu và phát hành văn bản đúng quy trình, đúng thẩm quyền. - Minh chứng: Sổ công văn, hồ sơ văn thư, sổ đóng dấu, quy trình phát hành | O1: Tiêu chí 17: Quản lý cơ sở vật chất, điện nước, sửa chữa, bảo trì, phương tiện, tổ xe, tổ bảo vệ theo kế hoạch. - Minh chứng: Kế hoạch bảo trì, phiếu sửa chữa, sổ xe, lịch trực bảo vệ | P1: Tiêu chí 18: Tổ chức an ninh trật tự, kiểm soát cổng, bãi xe, hàng rong, quảng cáo, taxi/xe dịch vụ; xử lý phản ánh kịp thời. - Minh chứng: Sổ trực bảo vệ, biên bản xử lý, camera, phản ánh người bệnh | Q1: Tiêu chí 20: Có phương án phòng cháy chữa cháy, an toàn điện, thang máy, thiên tai và sự cố hạ tầng; diễn tập/kiểm tra định kỳ. - Minh chứng: Hồ sơ PCCC, sổ kiểm tra thang máy/điện, phương án ứng phó | R1: Ghi chú / Phát hiện / Yêu cầu khắc phục của Ông Dương Quốc Huy | S1: Tiêu chí 13: Khu vực làm việc, kho hồ sơ, nơi tiếp nhận người bệnh/người nhà nếu có bảo đảm vệ sinh, phân loại rác, phòng chống lây nhiễm phù hợp. - Minh chứng: Quan sát, thùng rác, vệ sinh bề mặt, hướng dẫn vệ sinh tay | T1: Tiêu chí 14: Khi tiếp xúc người bệnh/người nhà/nhân viên, thực hiện giao tiếp ứng xử đúng quy định, hướng dẫn rõ ràng, tôn trọng và bảo mật thông tin. - Minh chứng: Quan sát, phản ánh, phiếu khảo sát, hồ sơ tiếp nhận xử lý | U1: Tiêu chí 19: Giám sát vệ sinh ngoại cảnh, nhà vệ sinh, hành lang, khu công cộng; bảo đảm xanh - sạch - đẹp toàn viện. - Minh chứng: Lịch vệ sinh, biên bản giám sát, hình ảnh, phản ánh | V1: Ghi chú / Phát hiện / Yêu cầu khắc phục của Ông Trương Văn Khanh | W1: Tiêu chí 6: Có theo dõi chỉ tiêu/KPI/BI được giao; phát hiện vấn đề và đề xuất cải tiến trong phạm vi chức năng. - Minh chứng: Bảng theo dõi KPI/BI, báo cáo phân tích, kế hoạch cải tiến | X1: Tiêu chí 7: Thực hiện khắc phục sau kiểm tra/giám sát đúng thời hạn; có bằng chứng CAPA và đánh giá hiệu lực. - Minh chứng: Biên bản kiểm tra, kế hoạch CAPA, minh chứng hoàn thành | Y1: Tiêu chí 8: Tuân thủ bảo mật thông tin, không chia sẻ tài khoản/mật khẩu; dữ liệu, văn bản điện tử được phân quyền và sao lưu phù hợp. - Minh chứng: Tài khoản phần mềm, phân quyền, nhật ký truy cập, hồ sơ sao lưu | Z1: Tiêu chí 9: Máy tính, phần mềm, email công vụ và thiết bị lưu trữ được sử dụng đúng mục đích; không cài đặt phần mềm không rõ nguồn gốc. - Minh chứng: Kiểm tra máy trạm, phần mềm, email, USB/ổ cứng nếu có | AA1: Tiêu chí 15: Có ghi nhận, xử lý phản ánh, kiến nghị, khảo sát sự hài lòng liên quan đến phạm vi phòng; chuyển đúng đầu mối khi vượt thẩm quyền. - Minh chứng: Sổ/phần mềm phản ánh, phiếu khảo sát, biên bản xử lý | AB1: Ghi chú / Phát hiện / Yêu cầu khắc phục của Ông Trần Việt Hùng | AC1: TỔNG ĐIỂM PHÒNG | AD1: TỔNG HỢP NHẬN XÉT

Sheet Phản hồi - Phòng Công tác xã hộ
A1: Dấu thời gian | B1: XÁC NHẬN THÀNH VIÊN ĐOÀN 02 THỰC HIỆN CHẤM ĐIỂM | C1: Tiêu chí 4: Nhân viên có mặt đúng giờ, đúng vị trí; trang phục, bảng tên, giao tiếp, tác phong hành chính đúng quy định. - Minh chứng: Bảng chấm công, lịch trực/làm việc, quan sát trực tiếp | D1: Tiêu chí 5: Không sử dụng thời gian làm việc cho việc cá nhân không phù hợp nhiệm vụ; không để tồn đọng công việc do lỗi chủ quan. - Minh chứng: Quan sát, phản ánh, hồ sơ công việc tồn đọng, biên bản nhắc nhở | E1: Ghi chú / Phát hiện / Yêu cầu khắc phục của Bà Phan Hồng Trên | F1: Tiêu chí 2: Thực hiện báo cáo định kỳ/đột xuất đúng thời hạn, đúng biểu mẫu, số liệu thống nhất với hồ sơ gốc. - Minh chứng: Báo cáo tháng/quý, sổ giao nhận, email/văn bản gửi, file dữ liệu | G1: Tiêu chí 3: Lưu trữ văn bản, hồ sơ, sổ sách của phòng đầy đủ, dễ tra cứu, có phân loại và kiểm soát phiên bản. - Minh chứng: Hồ sơ lưu, danh mục hồ sơ, bìa hồ sơ, file điện tử | H1: Ghi chú / Phát hiện / Yêu cầu khắc phục của Bà Trần Kim Diệu | I1: Tiêu chí 1: Có kế hoạch công tác tháng/tuần, phân công nhiệm vụ cụ thể, cập nhật tiến độ thực hiện và có bằng chứng điều hành. - Minh chứng: Kế hoạch công tác, lịch phân công, biên bản giao ban, bảng theo dõi tiến độ | J1: Ghi chú / Phát hiện / Yêu cầu khắc phục của Bà Trần Thiên Lý | K1: Tiêu chí 10: Quản lý, sử dụng tài sản công, trang thiết bị, vật tư văn phòng tiết kiệm; có sổ theo dõi và bàn giao khi thay đổi người sử dụng. - Minh chứng: Sổ tài sản, biên bản bàn giao, phiếu cấp phát, kiểm kê | L1: Tiêu chí 11: Thực hiện tiết kiệm điện, nước, văn phòng phẩm; khu vực làm việc gọn gàng, xanh - sạch - đẹp, không nguy cơ cháy nổ. - Minh chứng: Quan sát thực tế, bảng nhắc tiết kiệm, tình trạng ổ điện, vật dụng | M1: Tiêu chí 12: Chấp hành quy định an toàn, trật tự, kiểm soát ra vào; phối hợp ngăn ngừa buôn bán, quảng cáo hàng rong, taxi/xe dịch vụ chèo kéo trong phạm vi quản lý. - Minh chứng: Quan sát, phản ánh, biên bản xử lý, phối hợp bảo vệ | N1: Tiêu chí 18: Quản lý hoạt động thiện nguyện, quà tặng, tài trợ, hỗ trợ bệnh nhân đúng quy định, công khai và minh bạch. - Minh chứng: Biên bản tiếp nhận, danh sách cấp phát, hồ sơ tài trợ, công khai | O1: Tiêu chí 19: Phối hợp hướng dẫn giờ thăm nuôi, trật tự khoa phòng, phòng chống chèo kéo, quảng cáo, bán hàng rong, taxi không đúng quy định. - Minh chứng: Biên bản phối hợp, nội dung truyền thông, phản ánh, quan sát | P1: Ghi chú / Phát hiện / Yêu cầu khắc phục của Ông Dương Quốc Huy | Q1: Tiêu chí 13: Khu vực làm việc, kho hồ sơ, nơi tiếp nhận người bệnh/người nhà nếu có bảo đảm vệ sinh, phân loại rác, phòng chống lây nhiễm phù hợp. - Minh chứng: Quan sát, thùng rác, vệ sinh bề mặt, hướng dẫn vệ sinh tay | R1: Tiêu chí 14: Khi tiếp xúc người bệnh/người nhà/nhân viên, thực hiện giao tiếp ứng xử đúng quy định, hướng dẫn rõ ràng, tôn trọng và bảo mật thông tin. - Minh chứng: Quan sát, phản ánh, phiếu khảo sát, hồ sơ tiếp nhận xử lý | S1: Tiêu chí 16: Tổ chức tiếp nhận, hỗ trợ, tư vấn, hướng dẫn người bệnh/người nhà; ghi nhận đầy đủ trường hợp cần hỗ trợ xã hội. - Minh chứng: Sổ CTXH, hồ sơ hỗ trợ, danh sách người bệnh cần hỗ trợ | T1: Ghi chú / Phát hiện / Yêu cầu khắc phục của Ông Trương Văn Khanh | U1: Tiêu chí 6: Có theo dõi chỉ tiêu/KPI/BI được giao; phát hiện vấn đề và đề xuất cải tiến trong phạm vi chức năng. - Minh chứng: Bảng theo dõi KPI/BI, báo cáo phân tích, kế hoạch cải tiến | V1: Tiêu chí 7: Thực hiện khắc phục sau kiểm tra/giám sát đúng thời hạn; có bằng chứng CAPA và đánh giá hiệu lực. - Minh chứng: Biên bản kiểm tra, kế hoạch CAPA, minh chứng hoàn thành | W1: Tiêu chí 8: Tuân thủ bảo mật thông tin, không chia sẻ tài khoản/mật khẩu; dữ liệu, văn bản điện tử được phân quyền và sao lưu phù hợp. - Minh chứng: Tài khoản phần mềm, phân quyền, nhật ký truy cập, hồ sơ sao lưu | X1: Tiêu chí 9: Máy tính, phần mềm, email công vụ và thiết bị lưu trữ được sử dụng đúng mục đích; không cài đặt phần mềm không rõ nguồn gốc. - Minh chứng: Kiểm tra máy trạm, phần mềm, email, USB/ổ cứng nếu có | Y1: Tiêu chí 15: Có ghi nhận, xử lý phản ánh, kiến nghị, khảo sát sự hài lòng liên quan đến phạm vi phòng; chuyển đúng đầu mối khi vượt thẩm quyền. - Minh chứng: Sổ/phần mềm phản ánh, phiếu khảo sát, biên bản xử lý | Z1: Tiêu chí 17: Phối hợp khảo sát hài lòng, tiếp nhận phản ánh, truyền thông giáo dục sức khỏe và cải thiện trải nghiệm người bệnh. - Minh chứng: Phiếu khảo sát, sổ phản ánh, kế hoạch truyền thông, báo cáo | AA1: Tiêu chí 20: Bảo mật thông tin người bệnh, hoàn cảnh xã hội, hình ảnh truyền thông; chỉ sử dụng khi có sự đồng ý/thẩm quyền. - Minh chứng: Phiếu đồng ý, hồ sơ truyền thông, phân quyền dữ liệu | AB1: Ghi chú / Phát hiện / Yêu cầu khắc phục của Ông Trần Việt Hùng | AC1: TỔNG ĐIỂM PHÒNG | AD1: TỔNG HỢP NHẬN XÉT

Sheet MUC_LUC
A1: PHIẾU KIỂM TRA VÀ CHẤM ĐIỂM KHỐI HÀNH CHÍNH - BỆNH VIỆN SẢN NHI CÀ MAU
A2: Thang điểm 100: 20 nội dung × 05 điểm; có phân công người phụ trách chấm điểm của Đoàn 01 và Đoàn 02.
A4: STT | B4: Khối | C4: Tên phòng | D4: Tên sheet | E4: Số nội dung | F4: Tổng điểm
A5: 1 | B5: Phòng chức năng | C5: Phòng Kế hoạch tổng hợp | D5: P_KHTH | E5: 20 | F5: 100
A6: 2 | B6: Phòng chức năng | C6: Phòng Quản lý chất lượng | D6: P_QLCL | E6: 20 | F6: 100
A7: 3 | B7: Phòng chức năng | C7: Phòng Tổ chức cán bộ | D7: P_TCCB | E7: 20 | F7: 100
A8: 4 | B8: Phòng chức năng | C8: Phòng Hành chánh quản trị | D8: P_HCQT | E8: 20 | F8: 100
A9: 5 | B9: Phòng chức năng | C9: Phòng Điều dưỡng | D9: P_DIEU_DUONG | E9: 20 | F9: 100
A10: 6 | B10: Phòng chức năng | C10: Phòng Tài chánh kế toán | D10: P_TCKT | E10: 20 | F10: 100
A11: 7 | B11: Phòng chức năng | C11: Phòng Vật tư thiết bị y tế | D11: P_VTTBYT | E11: 20 | F11: 100
A12: 8 | B12: Phòng chức năng | C12: Phòng Công tác xã hội | D12: P_CTXH | E12: 20 | F12: 100

Sheet HUONG_DAN
A1: Nội dung | B1: Hướng dẫn
A2: Phạm vi | B2: Áp dụng cho 08 phòng chức năng khối hành chính của Bệnh viện Sản - Nhi Cà Mau.
A3: Thang điểm | B3: Mỗi phiếu gồm 20 nội dung, mỗi nội dung tối đa 05 điểm, tổng 100 điểm.
A4: Cách chấm | B4: 0 điểm: không thực hiện/không có minh chứng; 1-2 điểm: thực hiện rất hạn chế; 3 điểm: đạt mức tối thiểu; 4 điểm: đạt tốt nhưng còn điểm nhỏ; 5 điểm: đạt đầy đủ, có minh chứng rõ.
A5: Xếp loại | B5: ≥90: Tốt; 80-<90: Khá; 65-<80: Đạt; <65: Chưa đạt/cần khắc phục ưu tiên.
A6: Nguyên tắc | B6: Không chấm hình thức; mọi điểm trừ phải ghi phát hiện, minh chứng, yêu cầu khắc phục, thời hạn và bộ phận chịu trách nhiệm.
A7: Phân công | B7: Tên người phụ trách Đoàn 01 và Đoàn 02 được ghi tại từng nội dung để thuận tiện phân công khi đi kiểm tra.

Sheet PHAN_CONG_02_DOAN
A1: Đoàn | B1: Họ và tên | C1: Chức vụ/đơn vị | D1: Vai trò | E1: Nhóm nội dung phụ trách chính
A2: Đoàn 01 | B2: Ông Nguyễn Việt Trí | C2: Trưởng phòng Kế hoạch tổng hợp | D2: Trưởng đoàn | E2: Quản trị, KHTH, chuyên môn phối hợp, hồ sơ/báo cáo
A3: Đoàn 01 | B3: Ông Triệu Quốc Nhượng | C3: Trưởng phòng Điều dưỡng | D3: Phó Trưởng đoàn | E3: Nhân lực điều dưỡng, giao tiếp, chăm sóc phục vụ
A4: Đoàn 01 | B4: Ông Đỗ Văn Dương | C4: Trưởng phòng Hành chính quản trị | D4: Thành viên | E4: Hành chính, tài sản, an ninh trật tự, cơ sở vật chất
A5: Đoàn 01 | B5: Ông Trịnh Như Anh | C5: Phó Trưởng khoa Dược | D5: Thành viên | E5: Dược, vật tư, cấp phát, quản lý kho liên quan
A6: Đoàn 01 | B6: Ông Bùi Duy Bình | C6: Tổ trưởng tổ Công nghệ thông tin | D6: Thành viên | E6: CNTT, bảo mật, an toàn thông tin mạng
A7: Đoàn 01 | B7: Ông Lý Quốc Tuyển | C7: Điều dưỡng trưởng Khoa KSNK | D7: Thành viên | E7: Kiểm soát nhiễm khuẩn, vệ sinh, chất thải
A8: Đoàn 01 | B8: Ông Nguyễn Chí Nguyện | C8: Phó trưởng khoa Truyền Nhiễm | D8: Thành viên | E8: Chuyên môn phối hợp, phòng chống dịch, an toàn người bệnh
A9: Đoàn 01 | B9: Bà Nguyễn Thị Lam | C9: Phòng Kế hoạch tổng hợp | D9: Thư ký | E9: Thư ký, hồ sơ kiểm tra, tổng hợp biên bản
A10: Đoàn 02 | B10: Bà Trần Thiên Lý | C10: Phó Giám đốc | D10: Trưởng đoàn | E10: Chỉ đạo chung, quản trị điều hành, xử lý nguy cơ
A11: Đoàn 02 | B11: Bà Phan Hồng Trên | C11: Phó phụ trách Phòng Tổ chức cán bộ | D11: Phó Trưởng đoàn | E11: Nhân sự, kỷ luật lao động, chấm công
A12: Đoàn 02 | B12: Bà Lưu Thị Thu Cầm | C12: Trưởng phòng Vật tư trang thiết bị y tế | D12: Thành viên | E12: Vật tư, trang thiết bị, hóa chất, bảo trì
... A17: Đoàn 02 | B17: Bà Trần Kim Diệu | C17: Phòng Quản lý chất lượng | D17: Thư ký | E17: Thư ký, tổng hợp QLCL, phiếu khảo sát/biên bản

Sheet CAN_CU
A1: STT | B1: Căn cứ/nguồn tham khảo | C1: Ghi chú
A2: 1 | B2: Quyết định thành lập 02 Đoàn kiểm tra hoạt động Bệnh viện năm 2026 của Bệnh viện Sản - Nhi Cà Mau | C2: Nguồn thành viên, vai trò và nguyên tắc hoạt động 02 đoàn
A3: 2 | B3: File 1405_03_thanh vien_Lich_kiem_tra_va_bang_kiem_HDBV_2026 | C3: Nguồn cấu trúc lịch, bảng kiểm chung và phân công thành viên phụ trách
A4: 3 | B4: Quy chế bệnh viện ban hành kèm Quyết định 1895/1997/BYT-QĐ | C4: Căn cứ quy chế hoạt động và quản lý bệnh viện
A5: 4 | B5: Luật Khám bệnh, chữa bệnh năm 2023 và văn bản hướng dẫn | C5: Căn cứ chung về hoạt động khám bệnh, chữa bệnh
A6: 5 | B6: Thông tư 19/2013/TT-BYT | C6: Quản lý chất lượng dịch vụ khám bệnh, chữa bệnh
A7: 6 | B7: Thông tư 43/2018/TT-BYT | C7: Phòng ngừa sự cố y khoa
A8: 7 | B8: Bộ tiêu chí chất lượng bệnh viện Việt Nam ban hành kèm Quyết định 6858/QĐ-BYT và văn bản cập nhật | C8: Tham chiếu tiêu chí chất lượng, an toàn người bệnh, hài lòng

Sheet P_KHTH
A1: PHIẾU KIỂM TRA VÀ CHẤM ĐIỂM - PHÒNG KẾ HOẠCH TỔNG HỢP
A2: Thang điểm 100 điểm: 20 nội dung × 05 điểm. Đơn vị: Phòng Kế hoạch tổng hợp. Ngày kiểm tra: ........../........../2026
A3: Đoàn kiểm tra | B3: Đơn vị được kiểm tra | C3: Trưởng khoa/phòng tiếp đoàn
A4: Đoàn 01 / Đoàn 02 | B4: Phòng Kế hoạch tổng hợp | C4: ................................
A6: STT | B6: Mã nhóm | C6: Nhóm nội dung | D6: Nội dung kiểm tra/chấm điểm | E6: Minh chứng cần xem | F6: Điểm tối đa | G6: Điểm đạt | H6: Tỷ lệ đạt | I6: Thành viên phụ trách Đoàn 01 | J6: Thành viên phụ trách Đoàn 02 | K6: Lý do trừ điểm / phát hiện | L6: Yêu cầu khắc phục | M6: Thời hạn | N6: Bộ phận chịu trách nhiệm | O6: Ghi chú
A7: 1 | B7: A | C7: Quản trị điều hành | D7: Có kế hoạch công tác tháng/tuần, phân công nhiệm vụ cụ thể, cập nhật tiến độ thực hiện và có bằng chứng điều hành. | E7: Kế hoạch công tác, lịch phân công, biên bản giao ban, bảng theo dõi tiến độ | F7: 5 | H7: =IF(G7="","",G7/F7) | I7: Ông Nguyễn Việt Trí | J7: Bà Trần Thiên Lý | N7: Phòng Kế hoạch tổng hợp
A8: 2 | B8: A | C8: Báo cáo - thống kê | D8: Thực hiện báo cáo định kỳ/đột xuất đúng thời hạn, đúng biểu mẫu, số liệu thống nhất với hồ sơ gốc. | E8: Báo cáo tháng/quý, sổ giao nhận, email/văn bản gửi, file dữ liệu | F8: 5 | H8: =IF(G8="","",G8/F8) | I8: Bà Nguyễn Thị Lam | J8: Bà Trần Kim Diệu | N8: Phòng Kế hoạch tổng hợp
A9: 3 | B9: A | C9: Thư ký - hồ sơ | D9: Lưu trữ văn bản, hồ sơ, sổ sách của phòng đầy đủ, dễ tra cứu, có phân loại và kiểm soát phiên bản. | E9: Hồ sơ lưu, danh mục hồ sơ, bìa hồ sơ, file điện tử | F9: 5 | H9: =IF(G9="","",G9/F9) | I9: Bà Nguyễn Thị Lam | J9: Bà Trần Kim Diệu | N9: Phòng Kế hoạch tổng hợp
A10: 4 | B10: B | C10: Nhân sự - kỷ luật | D10: Nhân viên có mặt đúng giờ, đúng vị trí; trang phục, bảng tên, giao tiếp, tác phong hành chính đúng quy định. | E10: Bảng chấm công, lịch trực/làm việc, quan sát trực tiếp | F10: 5 | H10: =IF(G10="","",G10/F10) | I10: Ông Triệu Quốc Nhượng | J10: Bà Phan Hồng Trên | N10: Phòng Kế hoạch tổng hợp
A11: 5 | B11: B | C11: Nhân sự - kỷ luật | D11: Không sử dụng thời gian làm việc cho việc cá nhân không phù hợp nhiệm vụ; không để tồn đọng công việc do lỗi chủ quan. | E11: Quan sát, phản ánh, hồ sơ công việc tồn đọng, biên bản nhắc nhở | F11: 5 | H11: =IF(G11="","",G11/F11) | I11: Ông Triệu Quốc Nhượng | J11: Bà Phan Hồng Trên | N11: Phòng Kế hoạch tổng hợp
A12: 6 | B12: C | C12: Quản lý chất lượng | D12: Có theo dõi chỉ tiêu/KPI/BI được giao; phát hiện vấn đề và đề xuất cải tiến trong phạm vi chức năng. | E12: Bảng theo dõi KPI/BI, báo cáo phân tích, kế hoạch cải tiến | F12: 5 | H12: =IF(G12="","",G12/F12) | I12: Ông Nguyễn Việt Trí | J12: Ông Trần Việt Hùng | N12: Phòng Kế hoạch tổng hợp
A13: 7 | B13: C | C13: Quản lý chất lượng | D13: Thực hiện khắc phục sau kiểm tra/giám sát đúng thời hạn; có bằng chứng CAPA và đánh giá hiệu lực. | E13: Biên bản kiểm tra, kế hoạch CAPA, minh chứng hoàn thành | F13: 5 | H13: =IF(G13="","",G13/F13) | I13: Ông Nguyễn Việt Trí | J13: Ông Trần Việt Hùng | N13: Phòng Kế hoạch tổng hợp
A14: 8 | B14: D | C14: CNTT - bảo mật | D14: Tuân thủ bảo mật thông tin, không chia sẻ tài khoản/mật khẩu; dữ liệu, văn bản điện tử được phân quyền và sao lưu phù hợp. | E14: Tài khoản phần mềm, phân quyền, nhật ký truy cập, hồ sơ sao lưu | F14: 5 | H14: =IF(G14="","",G14/F14) | I14: Ông Bùi Duy Bình | J14: Ông Trần Việt Hùng | N14: Phòng Kế hoạch tổng hợp
A15: 9 | B15: D | C15: CNTT - bảo mật | D15: Máy tính, phần mềm, email công vụ và thiết bị lưu trữ được sử dụng đúng mục đích; không cài đặt phần mềm không rõ nguồn gốc. | E15: Kiểm tra máy trạm, phần mềm, email, USB/ổ cứng nếu có | F15: 5 | H15: =IF(G15="","",G15/F15) | I15: Ông Bùi Duy Bình | J15: Ông Trần Việt Hùng | N15: Phòng Kế hoạch tổng hợp
A16: 10 | B16: E | C16: Hành chính - tài sản | D16: Quản lý, sử dụng tài sản công, trang thiết bị, vật tư văn phòng tiết kiệm; có sổ theo dõi và bàn giao khi thay đổi người sử dụng. | E16: Sổ tài sản, biên bản bàn giao, phiếu cấp phát, kiểm kê | F16: 5 | H16: =IF(G16="","",G16/F16) | I16: Ông Đỗ Văn Dương | J16: Ông Dương Quốc Huy | N16: Phòng Kế hoạch tổng hợp
A17: 11 | B17: E | C17: Hành chính - tài sản | D17: Thực hiện tiết kiệm điện, nước, văn phòng phẩm; khu vực làm việc gọn gàng, xanh - sạch - đẹp, không nguy cơ cháy nổ. | E17: Quan sát thực tế, bảng nhắc tiết kiệm, tình trạng ổ điện, vật dụng | F17: 5 | H17: =IF(G17="","",G17/F17) | I17: Ông Đỗ Văn Dương | J17: Ông Dương Quốc Huy | N17: Phòng Kế hoạch tổng hợp
A18: 12 | B18: F | C18: An ninh trật tự | D18: Chấp hành quy định an toàn, trật tự, kiểm soát ra vào; phối hợp ngăn ngừa buôn bán, quảng cáo hàng rong, taxi/xe dịch vụ chèo kéo trong phạm vi quản lý. | E18: Quan sát, phản ánh, biên bản xử lý, phối hợp bảo vệ | F18: 5 | H18: =IF(G18="","",G18/F18) | I18: Ông Đỗ Văn Dương | J18: Ông Dương Quốc Huy | N18: Phòng Kế hoạch tổng hợp
... A26: 20 | B26: H | C26: Chuyên môn phối hợp | D26: Phối hợp chỉ đạo tuyến, đào tạo, hội chẩn/chuyển tuyến, phòng chống dịch và các nhiệm vụ chuyên môn liên khoa đúng phân công. | E26: Kế hoạch, báo cáo, biên bản phối hợp, hồ sơ chỉ đạo tuyến | F26: 5 | H26: =IF(G26="","",G26/F26) | I26: Ông Nguyễn Chí Nguyện | J26: Bà Huỳnh Thúy Hằng | N26: Phòng Kế hoạch tổng hợp
A28: TỔNG ĐIỂM | G28: =SUM(G7:G26) -> 0 | H28: =G28/100 -> 0 | I28: =IF(G28>=90,"Tốt",IF(G28>=80,"Khá",IF(G28>=65,"Đạt","Chưa đạt"))) -> Chưa đạt
A30: Kết luận/kiến nghị của đoàn kiểm tra: ........................................................................................................................................................................................
A32: TRƯỞNG ĐOÀN | G32: THƯ KÝ | M32: ĐẠI DIỆN KHOA/PHÒNG

Sheet P_QLCL
A1: PHIẾU KIỂM TRA VÀ CHẤM ĐIỂM - PHÒNG QUẢN LÝ CHẤT LƯỢNG
A2: Thang điểm 100 điểm: 20 nội dung × 05 điểm. Đơn vị: Phòng Quản lý chất lượng. Ngày kiểm tra: ........../........../2026
A3: Đoàn kiểm tra | B3: Đơn vị được kiểm tra | C3: Trưởng khoa/phòng tiếp đoàn
A4: Đoàn 01 / Đoàn 02 | B4: Phòng Quản lý chất lượng | C4: ................................
A6: STT | B6: Mã nhóm | C6: Nhóm nội dung | D6: Nội dung kiểm tra/chấm điểm | E6: Minh chứng cần xem | F6: Điểm tối đa | G6: Điểm đạt | H6: Tỷ lệ đạt | I6: Thành viên phụ trách Đoàn 01 | J6: Thành viên phụ trách Đoàn 02 | K6: Lý do trừ điểm / phát hiện | L6: Yêu cầu khắc phục | M6: Thời hạn | N6: Bộ phận chịu trách nhiệm | O6: Ghi chú
A7: 1 | B7: A | C7: Quản trị điều hành | D7: Có kế hoạch công tác tháng/tuần, phân công nhiệm vụ cụ thể, cập nhật tiến độ thực hiện và có bằng chứng điều hành. | E7: Kế hoạch công tác, lịch phân công, biên bản giao ban, bảng theo dõi tiến độ | F7: 5 | H7: =IF(G7="","",G7/F7) | I7: Ông Nguyễn Việt Trí | J7: Bà Trần Thiên Lý | N7: Phòng Quản lý chất lượng
A8: 2 | B8: A | C8: Báo cáo - thống kê | D8: Thực hiện báo cáo định kỳ/đột xuất đúng thời hạn, đúng biểu mẫu, số liệu thống nhất với hồ sơ gốc. | E8: Báo cáo tháng/quý, sổ giao nhận, email/văn bản gửi, file dữ liệu | F8: 5 | H8: =IF(G8="","",G8/F8) | I8: Bà Nguyễn Thị Lam | J8: Bà Trần Kim Diệu | N8: Phòng Quản lý chất lượng
A9: 3 | B9: A | C9: Thư ký - hồ sơ | D9: Lưu trữ văn bản, hồ sơ, sổ sách của phòng đầy đủ, dễ tra cứu, có phân loại và kiểm soát phiên bản. | E9: Hồ sơ lưu, danh mục hồ sơ, bìa hồ sơ, file điện tử | F9: 5 | H9: =IF(G9="","",G9/F9) | I9: Bà Nguyễn Thị Lam | J9: Bà Trần Kim Diệu | N9: Phòng Quản lý chất lượng
A10: 4 | B10: B | C10: Nhân sự - kỷ luật | D10: Nhân viên có mặt đúng giờ, đúng vị trí; trang phục, bảng tên, giao tiếp, tác phong hành chính đúng quy định. | E10: Bảng chấm công, lịch trực/làm việc, quan sát trực tiếp | F10: 5 | H10: =IF(G10="","",G10/F10) | I10: Ông Triệu Quốc Nhượng | J10: Bà Phan Hồng Trên | N10: Phòng Quản lý chất lượng
A11: 5 | B11: B | C11: Nhân sự - kỷ luật | D11: Không sử dụng thời gian làm việc cho việc cá nhân không phù hợp nhiệm vụ; không để tồn đọng công việc do lỗi chủ quan. | E11: Quan sát, phản ánh, hồ sơ công việc tồn đọng, biên bản nhắc nhở | F11: 5 | H11: =IF(G11="","",G11/F11) | I11: Ông Triệu Quốc Nhượng | J11: Bà Phan Hồng Trên | N11: Phòng Quản lý chất lượng
A12: 6 | B12: C | C12: Quản lý chất lượng | D12: Có theo dõi chỉ tiêu/KPI/BI được giao; phát hiện vấn đề và đề xuất cải tiến trong phạm vi chức năng. | E12: Bảng theo dõi KPI/BI, báo cáo phân tích, kế hoạch cải tiến | F12: 5 | H12: =IF(G12="","",G12/F12) | I12: Ông Nguyễn Việt Trí | J12: Ông Trần Việt Hùng | N12: Phòng Quản lý chất lượng
A13: 7 | B13: C | C13: Quản lý chất lượng | D13: Thực hiện khắc phục sau kiểm tra/giám sát đúng thời hạn; có bằng chứng CAPA và đánh giá hiệu lực. | E13: Biên bản kiểm tra, kế hoạch CAPA, minh chứng hoàn thành | F13: 5 | H13: =IF(G13="","",G13/F13) | I13: Ông Nguyễn Việt Trí | J13: Ông Trần Việt Hùng | N13: Phòng Quản lý chất lượng
A14: 8 | B14: D | C14: CNTT - bảo mật | D14: Tuân thủ bảo mật thông tin, không chia sẻ tài khoản/mật khẩu; dữ liệu, văn bản điện tử được phân quyền và sao lưu phù hợp. | E14: Tài khoản phần mềm, phân quyền, nhật ký truy cập, hồ sơ sao lưu | F14: 5 | H14: =IF(G14="","",G14/F14) | I14: Ông Bùi Duy Bình | J14: Ông Trần Việt Hùng | N14: Phòng Quản lý chất lượng
A15: 9 | B15: D | C15: CNTT - bảo mật | D15: Máy tính, phần mềm, email công vụ và thiết bị lưu trữ được sử dụng đúng mục đích; không cài đặt phần mềm không rõ nguồn gốc. | E15: Kiểm tra máy trạm, phần mềm, email, USB/ổ cứng nếu có | F15: 5 | H15: =IF(G15="","",G15/F15) | I15: Ông Bùi Duy Bình | J15: Ông Trần Việt Hùng | N15: Phòng Quản lý chất lượng
A16: 10 | B16: E | C16: Hành chính - tài sản | D16: Quản lý, sử dụng tài sản công, trang thiết bị, vật tư văn phòng tiết kiệm; có sổ theo dõi và bàn giao khi thay đổi người sử dụng. | E16: Sổ tài sản, biên bản bàn giao, phiếu cấp phát, kiểm kê | F16: 5 | H16: =IF(G16="","",G16/F16) | I16: Ông Đỗ Văn Dương | J16: Ông Dương Quốc Huy | N16: Phòng Quản lý chất lượng
A17: 11 | B17: E | C17: Hành chính - tài sản | D17: Thực hiện tiết kiệm điện, nước, văn phòng phẩm; khu vực làm việc gọn gàng, xanh - sạch - đẹp, không nguy cơ cháy nổ. | E17: Quan sát thực tế, bảng nhắc tiết kiệm, tình trạng ổ điện, vật dụng | F17: 5 | H17: =IF(G17="","",G17/F17) | I17: Ông Đỗ Văn Dương | J17: Ông Dương Quốc Huy | N17: Phòng Quản lý chất lượng
A18: 12 | B18: F | C18: An ninh trật tự | D18: Chấp hành quy định an toàn, trật tự, kiểm soát ra vào; phối hợp ngăn ngừa buôn bán, quảng cáo hàng rong, taxi/xe dịch vụ chèo kéo trong phạm vi quản lý. | E18: Quan sát, phản ánh, biên bản xử lý, phối hợp bảo vệ | F18: 5 | H18: =IF(G18="","",G18/F18) | I18: Ông Đỗ Văn Dương | J18: Ông Dương Quốc Huy | N18: Phòng Quản lý chất lượng
... A26: 20 | B26: H | C26: CNTT - bảo mật | D26: Bảo mật dữ liệu khảo sát, sự cố và hồ sơ chất lượng; phân quyền, lưu trữ và công bố thông tin đúng quy định. | E26: Thư mục dữ liệu, phân quyền truy cập, hồ sơ công bố | F26: 5 | H26: =IF(G26="","",G26/F26) | I26: Ông Bùi Duy Bình | J26: Ông Trần Việt Hùng | N26: Phòng Quản lý chất lượng
A28: TỔNG ĐIỂM | G28: =SUM(G7:G26) -> 0 | H28: =G28/100 -> 0 | I28: =IF(G28>=90,"Tốt",IF(G28>=80,"Khá",IF(G28>=65,"Đạt","Chưa đạt"))) -> Chưa đạt
A30: Kết luận/kiến nghị của đoàn kiểm tra: ........................................................................................................................................................................................
A32: TRƯỞNG ĐOÀN | G32: THƯ KÝ | M32: ĐẠI DIỆN KHOA/PHÒNG

Sheet P_TCCB
A1: PHIẾU KIỂM TRA VÀ CHẤM ĐIỂM - PHÒNG TỔ CHỨC CÁN BỘ
A2: Thang điểm 100 điểm: 20 nội dung × 05 điểm. Đơn vị: Phòng Tổ chức cán bộ. Ngày kiểm tra: ........../........../2026
A3: Đoàn kiểm tra | B3: Đơn vị được kiểm tra | C3: Trưởng khoa/phòng tiếp đoàn
A4: Đoàn 01 / Đoàn 02 | B4: Phòng Tổ chức cán bộ | C4: ................................
A6: STT | B6: Mã nhóm | C6: Nhóm nội dung | D6: Nội dung kiểm tra/chấm điểm | E6: Minh chứng cần xem | F6: Điểm tối đa | G6: Điểm đạt | H6: Tỷ lệ đạt | I6: Thành viên phụ trách Đoàn 01 | J6: Thành viên phụ trách Đoàn 02 | K6: Lý do trừ điểm / phát hiện | L6: Yêu cầu khắc phục | M6: Thời hạn | N6: Bộ phận chịu trách nhiệm | O6: Ghi chú
A7: 1 | B7: A | C7: Quản trị điều hành | D7: Có kế hoạch công tác tháng/tuần, phân công nhiệm vụ cụ thể, cập nhật tiến độ thực hiện và có bằng chứng điều hành. | E7: Kế hoạch công tác, lịch phân công, biên bản giao ban, bảng theo dõi tiến độ | F7: 5 | H7: =IF(G7="","",G7/F7) | I7: Ông Nguyễn Việt Trí | J7: Bà Trần Thiên Lý | N7: Phòng Tổ chức cán bộ
A8: 2 | B8: A | C8: Báo cáo - thống kê | D8: Thực hiện báo cáo định kỳ/đột xuất đúng thời hạn, đúng biểu mẫu, số liệu thống nhất với hồ sơ gốc. | E8: Báo cáo tháng/quý, sổ giao nhận, email/văn bản gửi, file dữ liệu | F8: 5 | H8: =IF(G8="","",G8/F8) | I8: Bà Nguyễn Thị Lam | J8: Bà Trần Kim Diệu | N8: Phòng Tổ chức cán bộ
A9: 3 | B9: A | C9: Thư ký - hồ sơ | D9: Lưu trữ văn bản, hồ sơ, sổ sách của phòng đầy đủ, dễ tra cứu, có phân loại và kiểm soát phiên bản. | E9: Hồ sơ lưu, danh mục hồ sơ, bìa hồ sơ, file điện tử | F9: 5 | H9: =IF(G9="","",G9/F9) | I9: Bà Nguyễn Thị Lam | J9: Bà Trần Kim Diệu | N9: Phòng Tổ chức cán bộ
A10: 4 | B10: B | C10: Nhân sự - kỷ luật | D10: Nhân viên có mặt đúng giờ, đúng vị trí; trang phục, bảng tên, giao tiếp, tác phong hành chính đúng quy định. | E10: Bảng chấm công, lịch trực/làm việc, quan sát trực tiếp | F10: 5 | H10: =IF(G10="","",G10/F10) | I10: Ông Triệu Quốc Nhượng | J10: Bà Phan Hồng Trên | N10: Phòng Tổ chức cán bộ
A11: 5 | B11: B | C11: Nhân sự - kỷ luật | D11: Không sử dụng thời gian làm việc cho việc cá nhân không phù hợp nhiệm vụ; không để tồn đọng công việc do lỗi chủ quan. | E11: Quan sát, phản ánh, hồ sơ công việc tồn đọng, biên bản nhắc nhở | F11: 5 | H11: =IF(G11="","",G11/F11) | I11: Ông Triệu Quốc Nhượng | J11: Bà Phan Hồng Trên | N11: Phòng Tổ chức cán bộ
A12: 6 | B12: C | C12: Quản lý chất lượng | D12: Có theo dõi chỉ tiêu/KPI/BI được giao; phát hiện vấn đề và đề xuất cải tiến trong phạm vi chức năng. | E12: Bảng theo dõi KPI/BI, báo cáo phân tích, kế hoạch cải tiến | F12: 5 | H12: =IF(G12="","",G12/F12) | I12: Ông Nguyễn Việt Trí | J12: Ông Trần Việt Hùng | N12: Phòng Tổ chức cán bộ
A13: 7 | B13: C | C13: Quản lý chất lượng | D13: Thực hiện khắc phục sau kiểm tra/giám sát đúng thời hạn; có bằng chứng CAPA và đánh giá hiệu lực. | E13: Biên bản kiểm tra, kế hoạch CAPA, minh chứng hoàn thành | F13: 5 | H13: =IF(G13="","",G13/F13) | I13: Ông Nguyễn Việt Trí | J13: Ông Trần Việt Hùng | N13: Phòng Tổ chức cán bộ
A14: 8 | B14: D | C14: CNTT - bảo mật | D14: Tuân thủ bảo mật thông tin, không chia sẻ tài khoản/mật khẩu; dữ liệu, văn bản điện tử được phân quyền và sao lưu phù hợp. | E14: Tài khoản phần mềm, phân quyền, nhật ký truy cập, hồ sơ sao lưu | F14: 5 | H14: =IF(G14="","",G14/F14) | I14: Ông Bùi Duy Bình | J14: Ông Trần Việt Hùng | N14: Phòng Tổ chức cán bộ
A15: 9 | B15: D | C15: CNTT - bảo mật | D15: Máy tính, phần mềm, email công vụ và thiết bị lưu trữ được sử dụng đúng mục đích; không cài đặt phần mềm không rõ nguồn gốc. | E15: Kiểm tra máy trạm, phần mềm, email, USB/ổ cứng nếu có | F15: 5 | H15: =IF(G15="","",G15/F15) | I15: Ông Bùi Duy Bình | J15: Ông Trần Việt Hùng | N15: Phòng Tổ chức cán bộ
